Workbook
Name QZ_ACH: 'Quick Zone'!$C$13
Name QZ_ACHFail: 'Quick Zone'!$C$15
Name QZ_Activity: 'Quick Zone'!$C$8
Name QZ_AIT: 'Quick Zone Calc'!$C$13
Name QZ_Amount: 'Quick Zone'!$C$7
Name QZ_AntA: 'Quick Zone Calc'!$C$15
Name QZ_AntB: 'Quick Zone Calc'!$C$16
Name QZ_AntC: 'Quick Zone Calc'!$C$17
Name QZ_AtBP: 'Quick Zone Calc'!$C$31
Name QZ_Avail: 'Quick Zone'!$C$14
Name QZ_Basis0: 'Quick Zone Calc'!$C$110
Name QZ_Basis1: 'Quick Zone Calc'!$C$115
Name QZ_Basis2: 'Quick Zone Calc'!$C$120
Name QZ_BelowFP: 'Quick Zone Calc'!$C$30
Name QZ_BP: 'Quick Zone Calc'!$C$11
Name QZ_BundArea: 'Quick Zone'!$C$19
Name QZ_C: 'Quick Zone Calc'!$C$27
Name QZ_C2: 'Quick Zone Calc'!$C$28
Name QZ_Capped0: 'Quick Zone Calc'!$C$109
Name QZ_Capped1: 'Quick Zone Calc'!$C$114
Name QZ_Capped2: 'Quick Zone Calc'!$C$119
Name QZ_Cd: 'Quick Zone'!$C$29
Name QZ_DispRate: 'Quick Zone Calc'!$C$42
Name QZ_EPL0: 'Quick Zone Calc'!$C$98
Name QZ_EPL1: 'Quick Zone Calc'!$C$99
Name QZ_EPL2: 'Quick Zone Calc'!$C$100
Name QZ_Equip: 'Quick Zone Calc'!$C$122
Name QZ_EvapFlux: 'Quick Zone Calc'!$C$40
Name QZ_f: 'Quick Zone Calc'!$C$26
Name QZ_FillRate: 'Quick Zone'!$C$23
Name QZ_fIn: 'Quick Zone'!$C$26
Name QZ_fOut: 'Quick Zone'!$C$27
Name QZ_FP: 'Quick Zone Calc'!$C$12
Name QZ_FPMargin: 'Quick Zone'!$C$30
Name QZ_Gamma: 'Quick Zone Calc'!$C$9
Name QZ_Gov0: 'Quick Zone Calc'!$C$106
Name QZ_Gov1: 'Quick Zone Calc'!$C$111
Name QZ_Gov2: 'Quick Zone Calc'!$C$116
Name QZ_GovSized0: 'Quick Zone Calc'!$C$107
Name QZ_GovSized1: 'Quick Zone Calc'!$C$112
Name QZ_GovSized2: 'Quick Zone Calc'!$C$117
Name QZ_Group: 'Quick Zone Calc'!$C$14
Name QZ_Headline: 'Quick Zone Calc'!$C$82
Name QZ_Heavy: 'Quick Zone Calc'!$C$24
Name QZ_HoleArea: 'Quick Zone'!$C$28
Name QZ_Interior: 'Quick Zone Calc'!$C$32
Name QZ_IsGas: 'Quick Zone Calc'!$C$6
Name QZ_LELm: 'Quick Zone Calc'!$C$22
Name QZ_LFL: 'Quick Zone Calc'!$C$8
Name QZ_Limited: 'Quick Zone Calc'!$C$105
Name QZ_Location: 'Quick Zone'!$C$9
Name QZ_Low: 'Quick Zone Calc'!$C$104
Name QZ_M: 'Quick Zone Calc'!$C$7
Name QZ_M_All: 'Quick Zone Calc'!$C$48
Name QZ_M_Charge: 'Quick Zone Calc'!$C$50
Name QZ_M_Fill: 'Quick Zone Calc'!$C$49
Name QZ_MouthArea: 'Quick Zone'!$C$20
Name QZ_NE0: 'Quick Zone Calc'!$C$89
Name QZ_NE1: 'Quick Zone Calc'!$C$90
Name QZ_NE2: 'Quick Zone Calc'!$C$91

Sheet Quick Zone
B2: DSEAR Quick Zone | F2: Gas and vapour zoning to IEC 60079-10-1
B3: Pick a substance and an activity, then enter the amount. Yellow cells are inputs; everything else updates as you type.
B5: 1. What you’re handling | F5: Result
B6: Substance | C6: Toluene | D6: Add more on the Substances sheet | F6: =IF(QZ_Substance="","Choose a substance",QZ_Headline) -> Zone 0, Zone 1 and Zone 2
B7: Amount | C7: 25 | D7: =IF(QZ_Phase="Gas","kg of gas in the system","litres handled in one go") -> litres handled in one go | F7: =QZ_Subline -> Toluene · 25 litres · decanting / filling / sampling · indoors
B8: Activity | C8: Decanting / filling / sampling | D8: Sets which sources of release exist | F8: Zone | G8: Extent from the activity | I8: Equipment (EPL)
B9: Indoor or outdoor | C9: Indoor | F9: Zone 0 | G9: =QZ_Z0Text -> Inside the container | I9: =QZ_EPL0 -> Ga
B10: Temperature (°C) | C10: 20 | D10: Of the liquid or gas | G10: =QZ_Basis0 -> Vapour space inside the receiving container.
B11: Gas pressure (barg) | C11: 10 | D11: Gases only | F11: Zone 1 | G11: =QZ_Z1Text -> 0.52 m | I11: =QZ_EPL1 -> Gb
B12: Room volume (m³) | C12: 100 | D12: Indoors only | G12: =QZ_Basis1 -> Vapour pushed out of the container mouth while filling. Limited by the amount handled.
B13: Air changes per hour | C13: 3 | D13: 1 natural, 3–6 mechanical, 10+ LEV | F13: Zone 2 | G13: =QZ_Z2Text -> 2.65 m | I13: =QZ_EPL2 -> Gc
B14: Ventilation availability | C14: Good | D14: Fair or poor if it can fail | G14: =QZ_Basis2 -> Spill of the full amount.
B15: Air changes if ventilation fails | C15: 0.5 | D15: Closed building: about 0.25–1 | F15: Equipment | G15: =QZ_Equip -> Gas group IIA · temperature class T1 or better · AIT 480 °C
B17: 2. Assumptions | F17: Plan view
B18: Spill depth (mm) | C18: 5 | D18: Amount ÷ depth = pool area
B19: Bund or drip-tray area (m²) | D19: Optional. Caps the spill area
B20: Container mouth while filling (m²) | C20: 0.01 | D20: 0.01 m² is about 110 mm across
B21: Open surface: vessel, tin or tray (m²) | C21: 0.1 | D21: 0.1 m² is about 360 mm across
B22: Wet area: rag and wiped surface (m²) | C22: 0.2 | D22: Rags activity only
B23: Filling or charging rate (L/min) | C23: 20 | D23: Pushes vapour out of the opening
B24: Air speed over liquid, indoors (m/s) | C24: 0.3
B25: Air speed over liquid, outdoors (m/s) | C25: 0.5
B26: Ventilation efficiency f, indoors | C26: 2 | D26: 1 perfect mixing, 5 very poor
B27: Ventilation efficiency f, outdoors | C27: 1
B28: Gas leak hole area (mm²) | C28: 0.25 | D28: Small flange or valve, IEC Table B.1
B29: Discharge coefficient Cd | C29: 0.75
B30: Flash point margin (°C) | C30: 5 | D30: This far below flash point: no zone
B31: Safety factor k on LFL | C31: =TEXT(Tables!$B$15,"0.00")&" / "&TEXT(Tables!$B$16,"0.00")&" / "&TEXT(Tables!$B$17,"0.00") -> 0.25 / 0.25 / 0.50 | D31: Cont. / primary / secondary, on Tables
F32: Looking down on the point of activity. Rings are drawn to scale; the spoke shows metres.
B34: 3. How each zone is sized
B35: Grade of release | C35: Source of release | F35: Release (g/s) | G35: Ventilation | H35: Vz used (m³) | I35: Zone (IEC Table D.1)
B36: Continuous | C36: =IF(OR(QZ_Substance="",QZ_Sel=""),"",INDEX(QZ_SrcText,(QZ_Sel-1)*3+1)) -> Vapour space inside the receiving container | F36: =IF(OR(QZ_Substance="",QZ_Sel=""),"",IFERROR(INDEX(QZ_SrcRate,(QZ_Sel-1)*3+1)*1000,"–")) -> – | G36: =IF(OR(QZ_Substance="",QZ_Sel=""),"",INDEX(QZ_SrcDeg,(QZ_Sel-1)*3+1)) -> – | H36: =IF(OR(QZ_Substance="",QZ_Sel=""),"",INDEX(QZ_SrcVz,(QZ_Sel-1)*3+1)) -> – | I36: =IF(OR(QZ_Substance="",QZ_Sel=""),"",IF(NOT(INDEX(QZ_SrcApplies,(QZ_Sel-1)*3+1)),IF(QZ_IsGas,"None: no air inside","None: below flash point"),IF(NOT(INDEX(QZ_SrcSized,(QZ_Sel-1)*3+1)),"Zone 0 inside only",INDEX(QZ_SrcD1,(QZ_Sel-1)*3+1)))) -> Zone 0 inside only
B37: Primary | C37: =IF(OR(QZ_Substance="",QZ_Sel=""),"",INDEX(QZ_SrcText,(QZ_Sel-1)*3+2)) -> Vapour pushed out of the container mouth while filling | F37: =IF(OR(QZ_Substance="",QZ_Sel=""),"",IFERROR(INDEX(QZ_SrcRate,(QZ_Sel-1)*3+2)*1000,"–")) -> 0.037312266 | G37: =IF(OR(QZ_Substance="",QZ_Sel=""),"",INDEX(QZ_SrcDeg,(QZ_Sel-1)*3+2)) -> Medium | H37: =IF(OR(QZ_Substance="",QZ_Sel=""),"",INDEX(QZ_SrcVz,(QZ_Sel-1)*3+2)) -> 0.29218211 | I37: =IF(OR(QZ_Substance="",QZ_Sel=""),"",IF(NOT(INDEX(QZ_SrcApplies,(QZ_Sel-1)*3+2)),"None",IF(NOT(INDEX(QZ_SrcSized,(QZ_Sel-1)*3+2)),"Zone 0 inside only",INDEX(QZ_SrcD1,(QZ_Sel-1)*3+2)))) -> Zone 1
B38: Secondary | C38: =IF(OR(QZ_Substance="",QZ_Sel=""),"",INDEX(QZ_SrcText,(QZ_Sel-1)*3+3)) -> Spill of the full amount | F38: =IF(OR(QZ_Substance="",QZ_Sel=""),"",IFERROR(INDEX(QZ_SrcRate,(QZ_Sel-1)*3+3)*1000,"–")) -> 0.31249379 | G38: =IF(OR(QZ_Substance="",QZ_Sel=""),"",INDEX(QZ_SrcDeg,(QZ_Sel-1)*3+3)) -> Medium | H38: =IF(OR(QZ_Substance="",QZ_Sel=""),"",INDEX(QZ_SrcVz,(QZ_Sel-1)*3+3)) -> 39.152848 | I38: =IF(OR(QZ_Substance="",QZ_Sel=""),"",IF(NOT(INDEX(QZ_SrcApplies,(QZ_Sel-1)*3+3)),"None",IF(NOT(INDEX(QZ_SrcSized,(QZ_Sel-1)*3+3)),"Zone 0 inside only",INDEX(QZ_SrcD1,(QZ_Sel-1)*3+3)))) -> Zone 2
B40: 4. Compare activities
B41: Activity | C41: Zone 0 | F41: Zone 1 | H41: Zone 2 | J41: Highest EPL
B42: =Tables!$A$43 -> Closed containers / sealed system | C42: ='Quick Zone Calc'!$M$74 -> Inside the containers | F42: ='Quick Zone Calc'!$N$74 -> None | H42: ='Quick Zone Calc'!$O$74 -> 2.65 m | J42: ='Quick Zone Calc'!$AB$74 -> Ga
B43: =Tables!$A$44 -> Decanting / filling / sampling | C43: ='Quick Zone Calc'!$M$75 -> Inside the container | F43: ='Quick Zone Calc'!$N$75 -> 0.52 m | H43: ='Quick Zone Calc'!$O$75 -> 2.65 m | J43: ='Quick Zone Calc'!$AB$75 -> Ga
B44: =Tables!$A$45 -> Open vessel / continuous emission | C44: ='Quick Zone Calc'!$M$76 -> Inside + 0.91 m | F44: ='Quick Zone Calc'!$N$76 -> Within Zone 0 | H44: ='Quick Zone Calc'!$O$76 -> 2.65 m | J44: ='Quick Zone Calc'!$AB$76 -> Ga
B45: =Tables!$A$46 -> Open tin or tray | C45: ='Quick Zone Calc'!$M$77 -> Inside + 0.91 m | F45: ='Quick Zone Calc'!$N$77 -> None | H45: ='Quick Zone Calc'!$O$77 -> 2.65 m | J45: ='Quick Zone Calc'!$AB$77 -> Ga
...

Sheet Read Me
B2: DSEAR Zoning Calculator
B3: A screening tool for hazardous area classification under DSEAR. Gas and vapour zoning follows IEC 60079-10-1: release rate, hypothetical volume Vz, degree and availability of ventilation, then the zone, EPL, gas group and T-class. Dust zoning follows IEC 60079-10-2.
B4: Sheets
B5: Quick Zone: pick a substance, an activity and an amount, and get the Zone 0, 1 and 2 extents with a plan view.
B6: Gas-Vapour: one row per source of release, up to 50 rows. Yellow is input, grey is from the library and green is a result.
B7: Dust: one row per dust source, up to 40 rows.
B8: Substances and Dusts: material property libraries. Add rows to extend the dropdowns.
B9: Tables: constants, k factors, the zone matrix and the T-class table used by every formula.
B10: Quick Zone Calc: the workings behind Quick Zone, source by source.
B11: Why some activities have three zones
B12: Each source of release has one grade. A continuous grade gives Zone 0, a primary grade gives Zone 1 and a secondary grade gives Zone 2. One activity can involve several sources at once, and their zones nest inside each other.
B13: Decanting, filling and sampling have all three. The vapour space inside the receiving container is continuous (Zone 0), vapour pushed out of the container mouth while filling is primary (Zone 1), and a spill of the full amount is secondary (Zone 2).
... B52: • This workbook supports, and does not replace, a competent-person DSEAR assessment.

Sheet Gas-Vapour
A1: Gas and vapour sources: IEC 60079-10-1 hypothetical volume (Vz) method
A2: One row per source of release. Fill the yellow cells; grey cells come from the Substances sheet and green cells are results. Example rows 8 to 11 show the expected format, so overwrite or clear them.
A3: Vz is not the zone extent: the radius is an indicative size only. Final zone extents need assessor judgement (release direction, obstructions, heavier-than-air spread). See the Read Me sheet for equations and limitations.
B4: Input | D4: From library | F4: Calculation | H4: Result
A6: Inputs: source of release | U6: Substance data | AD6: Release rate | AL6: Ventilation and zone
A7: Ref | B7: Source of release / location | C7: Substance | D7: Release type | E7: Grade of release | F7: Indoor / Outdoor | G7: Pressure (barg) | H7: Process / liquid temp (°C) | I7: Ambient temp (°C) | J7: Hole area S (mm²) | K7: Discharge coeff. Cd | L7: Compress-ibility Z | M7: Vaporised fraction (liquid jet, blank = auto) | N7: Pool area (m²) | O7: Air velocity over pool (m/s) | P7: Vapour pressure override (kPa) | Q7: Room volume V0 (m³) | R7: Air changes per hour | S7: Ventilation efficiency f (1–5) | T7: Availability of ventilation | U7: M (kg/kmol) | V7: LFL (vol%) | W7: γ | X7: Liquid density (kg/m³) | Y7: Boiling point (°C) | Z7: Flash point (°C) | AA7: AIT (°C) | AB7: Gas group | AC7: Rel. vapour density (air = 1) | AD7: Pressure p (Pa abs) | AE7: Process temp T (K) | AF7: Ambient temp Ta (K) | AG7: Critical pressure pc (Pa abs) | AH7: Gas flow regime | AI7: Vapour pressure pv (kPa) | AJ7: Liquid discharge (kg/s) | AK7: Vapour release rate dG/dt (kg/s) | AL7: LELm (kg/m³) | AM7: k | AN7: (dV/dt)min (m³/s) | AO7: Air changes C (s⁻¹) | AP7: Hypothetical volume Vz (m³) | AQ7: Degree of ventilation | AR7: Persistence time t (min) | AS7: ZONE | AT7: Indicative radius, hemisphere of Vz (m) | AU7: Required EPL | AV7: Min. equipment group / T-class | AW7: Flags / notes
A8: G1 | B8: Propane line flange, LPG compound | C8: Propane | D8: Gas/vapour jet | E8: Secondary | F8: Outdoor | G8: 10 | H8: 20 | I8: 20 | J8: 2.5 | K8: 0.75 | L8: 1 | S8: 1 | T8: Good | U8: =IF($C8="","",IFERROR(IF(INDEX(Substances!$C$2:$C$60,MATCH($C8,Substances!$A$2:$A$60,0))="","",INDEX(Substances!$C$2:$C$60,MATCH($C8,Substances!$A$2:$A$60,0))),"—")) -> 44.1 | V8: =IF($C8="","",IFERROR(IF(INDEX(Substances!$D$2:$D$60,MATCH($C8,Substances!$A$2:$A$60,0))="","",INDEX(Substances!$D$2:$D$60,MATCH($C8,Substances!$A$2:$A$60,0))),"—")) -> 1.7 | W8: =IF($C8="","",IFERROR(IF(INDEX(Substances!$F$2:$F$60,MATCH($C8,Substances!$A$2:$A$60,0))="","",INDEX(Substances!$F$2:$F$60,MATCH($C8,Substances!$A$2:$A$60,0))),"—")) -> 1.13 | X8: =IF($C8="","",IFERROR(IF(INDEX(Substances!$G$2:$G$60,MATCH($C8,Substances!$A$2:$A$60,0))="","",INDEX(Substances!$G$2:$G$60,MATCH($C8,Substances!$A$2:$A$60,0))),"—")) -> 493 | Y8: =IF($C8="","",IFERROR(IF(INDEX(Substances!$H$2:$H$60,MATCH($C8,Substances!$A$2:$A$60,0))="","",INDEX(Substances!$H$2:$H$60,MATCH($C8,Substances!$A$2:$A$60,0))),"—")) -> -42.1 | Z8: =IF($C8="","",IFERROR(IF(INDEX(Substances!$I$2:$I$60,MATCH($C8,Substances!$A$2:$A$60,0))="","",INDEX(Substances!$I$2:$I$60,MATCH($C8,Substances!$A$2:$A$60,0))),"—")) | AA8: =IF($C8="","",IFERROR(IF(INDEX(Substances!$J$2:$J$60,MATCH($C8,Substances!$A$2:$A$60,0))="","",INDEX(Substances!$J$2:$J$60,MATCH($C8,Substances!$A$2:$A$60,0))),"—")) -> 450 | AB8: =IF($C8="","",IFERROR(IF(INDEX(Substances!$K$2:$K$60,MATCH($C8,Substances!$A$2:$A$60,0))="","",INDEX(Substances!$K$2:$K$60,MATCH($C8,Substances!$A$2:$A$60,0))),"—")) -> IIA | AC8: =IF($C8="","",IFERROR($U8/28.96,"—")) -> 1.5227901 | AD8: =IF($C8="","",IFERROR(N($G8)*100000+Tables!$B$4,"—")) -> 1101325 | AE8: =IF($C8="","",IFERROR($H8+273.15,"—")) -> 293.15 | AF8: =IF($C8="","",IFERROR($I8+273.15,"—")) -> 293.15 | AG8: =IF($C8="","",IFERROR(IF($D8="Gas/vapour jet",Tables!$B$4*(($W8+1)/2)^($W8/($W8-1)),"n/a"),"—")) -> 175165.2 | AH8: =IF($C8="","",IFERROR(IF($D8="Gas/vapour jet",IF($AD8>$AG8,"Choked","Subsonic"),"n/a"),"—")) -> Choked | AI8: =IF($C8="","",IFERROR(IF($D8="Gas/vapour jet","n/a",MIN(101.325,IF($P8<>"",$P8,IF(N(INDEX(Substances!$L$2:$L$60,MATCH($C8,Substances!$A$2:$A$60,0)))<>0,0.133322*10^(INDEX(Substances!$L$2:$L$60,MATCH($C8,Substances!$A$2:$A$60,0))-INDEX(Substances!$M$2:$M$60,MATCH($C8,Substances!$A$2:$A$60,0))/(INDEX(Substances!$N$2:$N$60,MATCH($C8,Substances!$A$2:$A$60,0))+$H8)),101.325*EXP(10.58*(1-($Y8+273.15)/$AE8)))))),"—")) -> n/a | AJ8: =IF($C8="","",IFERROR(IF($D8="Liquid jet",$K8*$J8*0.000001*SQRT(2*$X8*N($G8)*100000),"n/a"),"—")) -> n/a | AK8: =IF($C8="","",IFERROR(IF($D8="Gas/vapour jet",IF($AH8="Choked",$K8*$J8*0.000001*$AD8*SQRT($W8*$U8/($L8*Tables!$B$5*$AE8)*(2/($W8+1))^(($W8+1)/($W8-1))),$K8*$J8*0.000001*$AD8*SQRT($U8/($L8*Tables!$B$5*$AE8)*(2*$W8/($W8-1))*(1-(Tables!$B$4/$AD8)^(($W8-1)/$W8))*(Tables!$B$4/$AD8)^(2/$W8))),IF($D8="Liquid jet",$AJ8*IF($M8<>"",$M8,IF($H8>=$Y8,1,0)),6.55*$O8^0.78*$N8*$AI8*$U8^0.667/(Tables!$B$5*$AE8))),"—")) -> 0.0055740252 | AL8: =IF($C8="","",IFERROR(Tables!$B$10*$U8*$V8,"—")) -> 0.03118752 | AM8: =IF($C8="","",IFERROR(INDEX(Tables!$B$15:$B$17,MATCH($E8,Tables!$A$15:$A$17,0)),"—")) -> 0.5 | AN8: =IF($C8="","",IFERROR($AK8/($AM8*$AL8)*$AF8/Tables!$B$9,"—")) -> 0.35763528 | AO8: =IF($C8="","",IFERROR(IF($F8="Outdoor",Tables!$B$8,$R8/3600),"—")) -> 0.03 | AP8: =IF($C8="","",IFERROR($S8*$AN8/$AO8,"—")) -> 11.921176 | AQ8: =IF($C8="","",IFERROR(IF($AP8<Tables!$B$7,"High",IF($F8="Outdoor","Medium",IF($AP8<$Q8,"Medium","Low"))),"—")) -> Medium | AR8: =IF($C8="","",IFERROR(-$S8/$AO8*LN($V8*$AM8/Tables!$B$6)/60,"—")) -> 2.6487162 | AS8: =IF($C8="","",IFERROR(INDEX(Tables!$B$22:$J$24,MATCH($E8,Tables!$A$22:$A$24,0),MATCH($AQ8&"-"&$T8,Tables!$B$21:$J$21,0)),"—")) -> Zone 2 | AT8: =IF($C8="","",IFERROR((3*$AP8/(2*PI()))^(1/3),"—")) -> 1.7854739 | AU8: =IF($C8="","",IFERROR(IF(ISNUMBER(SEARCH("Zone 0",IFERROR(LEFT($AS8,FIND("(",$AS8)-1),$AS8))),"Ga",IF(ISNUMBER(SEARCH("Zone 1",IFERROR(LEFT($AS8,FIND("(",$AS8)-1),$AS8))),"Gb",IF(ISNUMBER(SEARCH("Zone 2",IFERROR(LEFT($AS8,FIND("(",$AS8)-1),$AS8))),"Gc","None required"))),"—")) -> Gc | AV8: =IF($C8="","",IFERROR(IF($AU8="None required","—",$AB8&" "&INDEX(Tables!$B$31:$B$37,MATCH($AA8-0.001,Tables!$A$31:$A$37,1))),"—")) -> IIA T2 | AW8: =IF($C8="","",TRIM(IF(IF(ISNUMBER($Z8),$H8<$Z8-5,FALSE()),"Handled >5°C below flash point — may not need zoning (unless mist/spray). ","")&IF(IF(AND($D8="Pool evaporation",ISNUMBER($Y8)),$H8>=$Y8,FALSE()),"Liquid at/above boiling point — pool equation not valid, treat as gas release. ","")&IF(IF(AND($D8="Liquid jet",$M8="",ISNUMBER($Y8)),$H8<$Y8,FALSE()),"Non-flashing liquid: vapour rate set to 0 — model the resulting pool on its own row. ","")&IF(AND($D8="Gas/vapour jet",NOT(ISNUMBER($W8))),"No γ in library for this substance. ","")&IF(IF(ISNUMBER($AC8),$AC8>1.2,FALSE()),"Heavier than air — extend zone at low level / into pits and drains. ","")&IF($AQ8="Low","Vz ≥ V0: ventilation cannot control the release — whole room affected. ","")&IF(AND($F8="Indoor",OR($Q8="",$R8="")),"Indoor: enter room volume and air changes. ",""))) -> Heavier than air — extend zone at low level / into pits and drains.
A9: G2 | B9: Natural gas regulator flange, boiler house | C9: Methane | D9: Gas/vapour jet | E9: Secondary | F9: Indoor | G9: 2 | H9: 20 | I9: 20 | J9: 1 | K9: 0.75 | L9: 1 | Q9: 200 | R9: 3 | S9: 2 | T9: Fair | U9: =IF($C9="","",IFERROR(IF(INDEX(Substances!$C$2:$C$60,MATCH($C9,Substances!$A$2:$A$60,0))="","",INDEX(Substances!$C$2:$C$60,MATCH($C9,Substances!$A$2:$A$60,0))),"—")) -> 16.04 | V9: =IF($C9="","",IFERROR(IF(INDEX(Substances!$D$2:$D$60,MATCH($C9,Substances!$A$2:$A$60,0))="","",INDEX(Substances!$D$2:$D$60,MATCH($C9,Substances!$A$2:$A$60,0))),"—")) -> 4.4 | W9: =IF($C9="","",IFERROR(IF(INDEX(Substances!$F$2:$F$60,MATCH($C9,Substances!$A$2:$A$60,0))="","",INDEX(Substances!$F$2:$F$60,MATCH($C9,Substances!$A$2:$A$60,0))),"—")) -> 1.31 | X9: =IF($C9="","",IFERROR(IF(INDEX(Substances!$G$2:$G$60,MATCH($C9,Substances!$A$2:$A$60,0))="","",INDEX(Substances!$G$2:$G$60,MATCH($C9,Substances!$A$2:$A$60,0))),"—")) | Y9: =IF($C9="","",IFERROR(IF(INDEX(Substances!$H$2:$H$60,MATCH($C9,Substances!$A$2:$A$60,0))="","",INDEX(Substances!$H$2:$H$60,MATCH($C9,Substances!$A$2:$A$60,0))),"—")) -> -161.5 | Z9: =IF($C9="","",IFERROR(IF(INDEX(Substances!$I$2:$I$60,MATCH($C9,Substances!$A$2:$A$60,0))="","",INDEX(Substances!$I$2:$I$60,MATCH($C9,Substances!$A$2:$A$60,0))),"—")) | AA9: =IF($C9="","",IFERROR(IF(INDEX(Substances!$J$2:$J$60,MATCH($C9,Substances!$A$2:$A$60,0))="","",INDEX(Substances!$J$2:$J$60,MATCH($C9,Substances!$A$2:$A$60,0))),"—")) -> 600 | AB9: =IF($C9="","",IFERROR(IF(INDEX(Substances!$K$2:$K$60,MATCH($C9,Substances!$A$2:$A$60,0))="","",INDEX(Substances!$K$2:$K$60,MATCH($C9,Substances!$A$2:$A$60,0))),"—")) -> IIA | AC9: =IF($C9="","",IFERROR($U9/28.96,"—")) -> 0.5538674 | AD9: =IF($C9="","",IFERROR(N($G9)*100000+Tables!$B$4,"—")) -> 301325 | AE9: =IF($C9="","",IFERROR($H9+273.15,"—")) -> 293.15 | AF9: =IF($C9="","",IFERROR($I9+273.15,"—")) -> 293.15 | AG9: =IF($C9="","",IFERROR(IF($D9="Gas/vapour jet",Tables!$B$4*(($W9+1)/2)^($W9/($W9-1)),"n/a"),"—")) -> 186284.18 | AH9: =IF($C9="","",IFERROR(IF($D9="Gas/vapour jet",IF($AD9>$AG9,"Choked","Subsonic"),"n/a"),"—")) -> Choked | AI9: =IF($C9="","",IFERROR(IF($D9="Gas/vapour jet","n/a",MIN(101.325,IF($P9<>"",$P9,IF(N(INDEX(Substances!$L$2:$L$60,MATCH($C9,Substances!$A$2:$A$60,0)))<>0,0.133322*10^(INDEX(Substances!$L$2:$L$60,MATCH($C9,Substances!$A$2:$A$60,0))-INDEX(Substances!$M$2:$M$60,MATCH($C9,Substances!$A$2:$A$60,0))/(INDEX(Substances!$N$2:$N$60,MATCH($C9,Substances!$A$2:$A$60,0))+$H9)),101.325*EXP(10.58*(1-($Y9+273.15)/$AE9)))))),"—")) -> n/a | AJ9: =IF($C9="","",IFERROR(IF($D9="Liquid jet",$K9*$J9*0.000001*SQRT(2*$X9*N($G9)*100000),"n/a"),"—")) -> n/a | AK9: =IF($C9="","",IFERROR(IF($D9="Gas/vapour jet",IF($AH9="Choked",$K9*$J9*0.000001*$AD9*SQRT($W9*$U9/($L9*Tables!$B$5*$AE9)*(2/($W9+1))^(($W9+1)/($W9-1))),$K9*$J9*0.000001*$AD9*SQRT($U9/($L9*Tables!$B$5*$AE9)*(2*$W9/($W9-1))*(1-(Tables!$B$4/$AD9)^(($W9-1)/$W9))*(Tables!$B$4/$AD9)^(2/$W9))),IF($D9="Liquid jet",$AJ9*IF($M9<>"",$M9,IF($H9>=$Y9,1,0)),6.55*$O9^0.78*$N9*$AI9*$U9^0.667/(Tables!$B$5*$AE9))),"—")) -> 0.00038789657 | AL9: =IF($C9="","",IFERROR(Tables!$B$10*$U9*$V9,"—")) -> 0.029359616 | AM9: =IF($C9="","",IFERROR(INDEX(Tables!$B$15:$B$17,MATCH($E9,Tables!$A$15:$A$17,0)),"—")) -> 0.5 | AN9: =IF($C9="","",IFERROR($AK9/($AM9*$AL9)*$AF9/Tables!$B$9,"—")) -> 0.026437345 | AO9: =IF($C9="","",IFERROR(IF($F9="Outdoor",Tables!$B$8,$R9/3600),"—")) -> 0.00083333333 | AP9: =IF($C9="","",IFERROR($S9*$AN9/$AO9,"—")) -> 63.449628 | AQ9: =IF($C9="","",IFERROR(IF($AP9<Tables!$B$7,"High",IF($F9="Outdoor","Medium",IF($AP9<$Q9,"Medium","Low"))),"—")) -> Medium | AR9: =IF($C9="","",IFERROR(-$S9/$AO9*LN($V9*$AM9/Tables!$B$6)/60,"—")) -> 152.66851 | AS9: =IF($C9="","",IFERROR(INDEX(Tables!$B$22:$J$24,MATCH($E9,Tables!$A$22:$A$24,0),MATCH($AQ9&"-"&$T9,Tables!$B$21:$J$21,0)),"—")) -> Zone 2 | AT9: =IF($C9="","",IFERROR((3*$AP9/(2*PI()))^(1/3),"—")) -> 3.117383 | AU9: =IF($C9="","",IFERROR(IF(ISNUMBER(SEARCH("Zone 0",IFERROR(LEFT($AS9,FIND("(",$AS9)-1),$AS9))),"Ga",IF(ISNUMBER(SEARCH("Zone 1",IFERROR(LEFT($AS9,FIND("(",$AS9)-1),$AS9))),"Gb",IF(ISNUMBER(SEARCH("Zone 2",IFERROR(LEFT($AS9,FIND("(",$AS9)-1),$AS9))),"Gc","None required"))),"—")) -> Gc | AV9: =IF($C9="","",IFERROR(IF($AU9="None required","—",$AB9&" "&INDEX(Tables!$B$31:$B$37,MATCH($AA9-0.001,Tables!$A$31:$A$37,1))),"—")) -> IIA T1 | AW9: =IF($C9="","",TRIM(IF(IF(ISNUMBER($Z9),$H9<$Z9-5,FALSE()),"Handled >5°C below flash point — may not need zoning (unless mist/spray). ","")&IF(IF(AND($D9="Pool evaporation",ISNUMBER($Y9)),$H9>=$Y9,FALSE()),"Liquid at/above boiling point — pool equation not valid, treat as gas release. ","")&IF(IF(AND($D9="Liquid jet",$M9="",ISNUMBER($Y9)),$H9<$Y9,FALSE()),"Non-flashing liquid: vapour rate set to 0 — model the resulting pool on its own row. ","")&IF(AND($D9="Gas/vapour jet",NOT(ISNUMBER($W9))),"No γ in library for this substance. ","")&IF(IF(ISNUMBER($AC9),$AC9>1.2,FALSE()),"Heavier than air — extend zone at low level / into pits and drains. ","")&IF($AQ9="Low","Vz ≥ V0: ventilation cannot control the release — whole room affected. ","")&IF(AND($F9="Indoor",OR($Q9="",$R9="")),"Indoor: enter room volume and air changes. ","")))
A10: L1 | B10: Toluene drum decanting, spill to bund, solvent store | C10: Toluene | D10: Pool evaporation | E10: Primary | F10: Indoor | H10: 20 | I10: 20 | N10: 1 | O10: 0.3 | Q10: 500 | R10: 6 | S10: 2 | T10: Good | U10: =IF($C10="","",IFERROR(IF(INDEX(Substances!$C$2:$C$60,MATCH($C10,Substances!$A$2:$A$60,0))="","",INDEX(Substances!$C$2:$C$60,MATCH($C10,Substances!$A$2:$A$60,0))),"—")) -> 92.14 | V10: =IF($C10="","",IFERROR(IF(INDEX(Substances!$D$2:$D$60,MATCH($C10,Substances!$A$2:$A$60,0))="","",INDEX(Substances!$D$2:$D$60,MATCH($C10,Substances!$A$2:$A$60,0))),"—")) -> 1 | W10: =IF($C10="","",IFERROR(IF(INDEX(Substances!$F$2:$F$60,MATCH($C10,Substances!$A$2:$A$60,0))="","",INDEX(Substances!$F$2:$F$60,MATCH($C10,Substances!$A$2:$A$60,0))),"—")) | X10: =IF($C10="","",IFERROR(IF(INDEX(Substances!$G$2:$G$60,MATCH($C10,Substances!$A$2:$A$60,0))="","",INDEX(Substances!$G$2:$G$60,MATCH($C10,Substances!$A$2:$A$60,0))),"—")) -> 867 | Y10: =IF($C10="","",IFERROR(IF(INDEX(Substances!$H$2:$H$60,MATCH($C10,Substances!$A$2:$A$60,0))="","",INDEX(Substances!$H$2:$H$60,MATCH($C10,Substances!$A$2:$A$60,0))),"—")) -> 110.6 | Z10: =IF($C10="","",IFERROR(IF(INDEX(Substances!$I$2:$I$60,MATCH($C10,Substances!$A$2:$A$60,0))="","",INDEX(Substances!$I$2:$I$60,MATCH($C10,Substances!$A$2:$A$60,0))),"—")) -> 4 | AA10: =IF($C10="","",IFERROR(IF(INDEX(Substances!$J$2:$J$60,MATCH($C10,Substances!$A$2:$A$60,0))="","",INDEX(Substances!$J$2:$J$60,MATCH($C10,Substances!$A$2:$A$60,0))),"—")) -> 480 | AB10: =IF($C10="","",IFERROR(IF(INDEX(Substances!$K$2:$K$60,MATCH($C10,Substances!$A$2:$A$60,0))="","",INDEX(Substances!$K$2:$K$60,MATCH($C10,Substances!$A$2:$A$60,0))),"—")) -> IIA | AC10: =IF($C10="","",IFERROR($U10/28.96,"—")) -> 3.1816298 | AD10: =IF($C10="","",IFERROR(N($G10)*100000+Tables!$B$4,"—")) -> 101325 | AE10: =IF($C10="","",IFERROR($H10+273.15,"—")) -> 293.15 | AF10: =IF($C10="","",IFERROR($I10+273.15,"—")) -> 293.15 | AG10: =IF($C10="","",IFERROR(IF($D10="Gas/vapour jet",Tables!$B$4*(($W10+1)/2)^($W10/($W10-1)),"n/a"),"—")) -> n/a | AH10: =IF($C10="","",IFERROR(IF($D10="Gas/vapour jet",IF($AD10>$AG10,"Choked","Subsonic"),"n/a"),"—")) -> n/a | AI10: =IF($C10="","",IFERROR(IF($D10="Gas/vapour jet","n/a",MIN(101.325,IF($P10<>"",$P10,IF(N(INDEX(Substances!$L$2:$L$60,MATCH($C10,Substances!$A$2:$A$60,0)))<>0,0.133322*10^(INDEX(Substances!$L$2:$L$60,MATCH($C10,Substances!$A$2:$A$60,0))-INDEX(Substances!$M$2:$M$60,MATCH($C10,Substances!$A$2:$A$60,0))/(INDEX(Substances!$N$2:$N$60,MATCH($C10,Substances!$A$2:$A$60,0))+$H10)),101.325*EXP(10.58*(1-($Y10+273.15)/$AE10)))))),"—")) -> 2.9113101 | AJ10: =IF($C10="","",IFERROR(IF($D10="Liquid jet",$K10*$J10*0.000001*SQRT(2*$X10*N($G10)*100000),"n/a"),"—")) -> n/a | AK10: =IF($C10="","",IFERROR(IF($D10="Gas/vapour jet",IF($AH10="Choked",$K10*$J10*0.000001*$AD10*SQRT($W10*$U10/($L10*Tables!$B$5*$AE10)*(2/($W10+1))^(($W10+1)/($W10-1))),$K10*$J10*0.000001*$AD10*SQRT($U10/($L10*Tables!$B$5*$AE10)*(2*$W10/($W10-1))*(1-(Tables!$B$4/$AD10)^(($W10-1)/$W10))*(Tables!$B$4/$AD10)^(2/$W10))),IF($D10="Liquid jet",$AJ10*IF($M10<>"",$M10,IF($H10>=$Y10,1,0)),6.55*$O10^0.78*$N10*$AI10*$U10^0.667/(Tables!$B$5*$AE10))),"—")) -> 6.2498757e-05 | AL10: =IF($C10="","",IFERROR(Tables!$B$10*$U10*$V10,"—")) -> 0.03833024 | AM10: =IF($C10="","",IFERROR(INDEX(Tables!$B$15:$B$17,MATCH($E10,Tables!$A$15:$A$17,0)),"—")) -> 0.25 | AN10: =IF($C10="","",IFERROR($AK10/($AM10*$AL10)*$AF10/Tables!$B$9,"—")) -> 0.0065254747 | AO10: =IF($C10="","",IFERROR(IF($F10="Outdoor",Tables!$B$8,$R10/3600),"—")) -> 0.0016666667 | AP10: =IF($C10="","",IFERROR($S10*$AN10/$AO10,"—")) -> 7.8305697 | AQ10: =IF($C10="","",IFERROR(IF($AP10<Tables!$B$7,"High",IF($F10="Outdoor","Medium",IF($AP10<$Q10,"Medium","Low"))),"—")) -> Medium | AR10: =IF($C10="","",IFERROR(-$S10/$AO10*LN($V10*$AM10/Tables!$B$6)/60,"—")) -> 119.82929 | AS10: =IF($C10="","",IFERROR(INDEX(Tables!$B$22:$J$24,MATCH($E10,Tables!$A$22:$A$24,0),MATCH($AQ10&"-"&$T10,Tables!$B$21:$J$21,0)),"—")) -> Zone 1 | AT10: =IF($C10="","",IFERROR((3*$AP10/(2*PI()))^(1/3),"—")) -> 1.552071 | AU10: =IF($C10="","",IFERROR(IF(ISNUMBER(SEARCH("Zone 0",IFERROR(LEFT($AS10,FIND("(",$AS10)-1),$AS10))),"Ga",IF(ISNUMBER(SEARCH("Zone 1",IFERROR(LEFT($AS10,FIND("(",$AS10)-1),$AS10))),"Gb",IF(ISNUMBER(SEARCH("Zone 2",IFERROR(LEFT($AS10,FIND("(",$AS10)-1),$AS10))),"Gc","None required"))),"—")) -> Gb | AV10: =IF($C10="","",IFERROR(IF($AU10="None required","—",$AB10&" "&INDEX(Tables!$B$31:$B$37,MATCH($AA10-0.001,Tables!$A$31:$A$37,1))),"—")) -> IIA T1 | AW10: =IF($C10="","",TRIM(IF(IF(ISNUMBER($Z10),$H10<$Z10-5,FALSE()),"Handled >5°C below flash point — may not need zoning (unless mist/spray). ","")&IF(IF(AND($D10="Pool evaporation",ISNUMBER($Y10)),$H10>=$Y10,FALSE()),"Liquid at/above boiling point — pool equation not valid, treat as gas release. ","")&IF(IF(AND($D10="Liquid jet",$M10="",ISNUMBER($Y10)),$H10<$Y10,FALSE()),"Non-flashing liquid: vapour rate set to 0 — model the resulting pool on its own row. ","")&IF(AND($D10="Gas/vapour jet",NOT(ISNUMBER($W10))),"No γ in library for this substance. ","")&IF(IF(ISNUMBER($AC10),$AC10>1.2,FALSE()),"Heavier than air — extend zone at low level / into pits and drains. ","")&IF($AQ10="Low","Vz ≥ V0: ventilation cannot control the release — whole room affected. ","")&IF(AND($F10="Indoor",OR($Q10="",$R10="")),"Indoor: enter room volume and air changes. ",""))) -> Heavier than air — extend zone at low level / into pits and drains.
A11: L2 | B11: LPG (butane) liquid pump seal, flashing release | C11: n-Butane | D11: Liquid jet | E11: Secondary | F11: Outdoor | G11: 3 | H11: 20 | I11: 20 | J11: 0.25 | K11: 0.75 | S11: 1 | T11: Good | U11: =IF($C11="","",IFERROR(IF(INDEX(Substances!$C$2:$C$60,MATCH($C11,Substances!$A$2:$A$60,0))="","",INDEX(Substances!$C$2:$C$60,MATCH($C11,Substances!$A$2:$A$60,0))),"—")) -> 58.12 | V11: =IF($C11="","",IFERROR(IF(INDEX(Substances!$D$2:$D$60,MATCH($C11,Substances!$A$2:$A$60,0))="","",INDEX(Substances!$D$2:$D$60,MATCH($C11,Substances!$A$2:$A$60,0))),"—")) -> 1.4 | W11: =IF($C11="","",IFERROR(IF(INDEX(Substances!$F$2:$F$60,MATCH($C11,Substances!$A$2:$A$60,0))="","",INDEX(Substances!$F$2:$F$60,MATCH($C11,Substances!$A$2:$A$60,0))),"—")) -> 1.1 | X11: =IF($C11="","",IFERROR(IF(INDEX(Substances!$G$2:$G$60,MATCH($C11,Substances!$A$2:$A$60,0))="","",INDEX(Substances!$G$2:$G$60,MATCH($C11,Substances!$A$2:$A$60,0))),"—")) -> 579 | Y11: =IF($C11="","",IFERROR(IF(INDEX(Substances!$H$2:$H$60,MATCH($C11,Substances!$A$2:$A$60,0))="","",INDEX(Substances!$H$2:$H$60,MATCH($C11,Substances!$A$2:$A$60,0))),"—")) -> -0.5 | Z11: =IF($C11="","",IFERROR(IF(INDEX(Substances!$I$2:$I$60,MATCH($C11,Substances!$A$2:$A$60,0))="","",INDEX(Substances!$I$2:$I$60,MATCH($C11,Substances!$A$2:$A$60,0))),"—")) | AA11: =IF($C11="","",IFERROR(IF(INDEX(Substances!$J$2:$J$60,MATCH($C11,Substances!$A$2:$A$60,0))="","",INDEX(Substances!$J$2:$J$60,MATCH($C11,Substances!$A$2:$A$60,0))),"—")) -> 372 | AB11: =IF($C11="","",IFERROR(IF(INDEX(Substances!$K$2:$K$60,MATCH($C11,Substances!$A$2:$A$60,0))="","",INDEX(Substances!$K$2:$K$60,MATCH($C11,Substances!$A$2:$A$60,0))),"—")) -> IIA | AC11: =IF($C11="","",IFERROR($U11/28.96,"—")) -> 2.0069061 | AD11: =IF($C11="","",IFERROR(N($G11)*100000+Tables!$B$4,"—")) -> 401325 | AE11: =IF($C11="","",IFERROR($H11+273.15,"—")) -> 293.15 | AF11: =IF($C11="","",IFERROR($I11+273.15,"—")) -> 293.15 | AG11: =IF($C11="","",IFERROR(IF($D11="Gas/vapour jet",Tables!$B$4*(($W11+1)/2)^($W11/($W11-1)),"n/a"),"—")) -> n/a | AH11: =IF($C11="","",IFERROR(IF($D11="Gas/vapour jet",IF($AD11>$AG11,"Choked","Subsonic"),"n/a"),"—")) -> n/a | AI11: =IF($C11="","",IFERROR(IF($D11="Gas/vapour jet","n/a",MIN(101.325,IF($P11<>"",$P11,IF(N(INDEX(Substances!$L$2:$L$60,MATCH($C11,Substances!$A$2:$A$60,0)))<>0,0.133322*10^(INDEX(Substances!$L$2:$L$60,MATCH($C11,Substances!$A$2:$A$60,0))-INDEX(Substances!$M$2:$M$60,MATCH($C11,Substances!$A$2:$A$60,0))/(INDEX(Substances!$N$2:$N$60,MATCH($C11,Substances!$A$2:$A$60,0))+$H11)),101.325*EXP(10.58*(1-($Y11+273.15)/$AE11)))))),"—")) -> 101.325 | AJ11: =IF($C11="","",IFERROR(IF($D11="Liquid jet",$K11*$J11*0.000001*SQRT(2*$X11*N($G11)*100000),"n/a"),"—")) -> 0.0034947505 | AK11: =IF($C11="","",IFERROR(IF($D11="Gas/vapour jet",IF($AH11="Choked",$K11*$J11*0.000001*$AD11*SQRT($W11*$U11/($L11*Tables!$B$5*$AE11)*(2/($W11+1))^(($W11+1)/($W11-1))),$K11*$J11*0.000001*$AD11*SQRT($U11/($L11*Tables!$B$5*$AE11)*(2*$W11/($W11-1))*(1-(Tables!$B$4/$AD11)^(($W11-1)/$W11))*(Tables!$B$4/$AD11)^(2/$W11))),IF($D11="Liquid jet",$AJ11*IF($M11<>"",$M11,IF($H11>=$Y11,1,0)),6.55*$O11^0.78*$N11*$AI11*$U11^0.667/(Tables!$B$5*$AE11))),"—")) -> 0.0034947505 | AL11: =IF($C11="","",IFERROR(Tables!$B$10*$U11*$V11,"—")) -> 0.033849088 | AM11: =IF($C11="","",IFERROR(INDEX(Tables!$B$15:$B$17,MATCH($E11,Tables!$A$15:$A$17,0)),"—")) -> 0.5 | AN11: =IF($C11="","",IFERROR($AK11/($AM11*$AL11)*$AF11/Tables!$B$9,"—")) -> 0.2065958 | AO11: =IF($C11="","",IFERROR(IF($F11="Outdoor",Tables!$B$8,$R11/3600),"—")) -> 0.03 | AP11: =IF($C11="","",IFERROR($S11*$AN11/$AO11,"—")) -> 6.8865266 | AQ11: =IF($C11="","",IFERROR(IF($AP11<Tables!$B$7,"High",IF($F11="Outdoor","Medium",IF($AP11<$Q11,"Medium","Low"))),"—")) -> Medium | AR11: =IF($C11="","",IFERROR(-$S11/$AO11*LN($V11*$AM11/Tables!$B$6)/60,"—")) -> 2.7565806 | AS11: =IF($C11="","",IFERROR(INDEX(Tables!$B$22:$J$24,MATCH($E11,Tables!$A$22:$A$24,0),MATCH($AQ11&"-"&$T11,Tables!$B$21:$J$21,0)),"—")) -> Zone 2 | AT11: =IF($C11="","",IFERROR((3*$AP11/(2*PI()))^(1/3),"—")) -> 1.4870099 | AU11: =IF($C11="","",IFERROR(IF(ISNUMBER(SEARCH("Zone 0",IFERROR(LEFT($AS11,FIND("(",$AS11)-1),$AS11))),"Ga",IF(ISNUMBER(SEARCH("Zone 1",IFERROR(LEFT($AS11,FIND("(",$AS11)-1),$AS11))),"Gb",IF(ISNUMBER(SEARCH("Zone 2",IFERROR(LEFT($AS11,FIND("(",$AS11)-1),$AS11))),"Gc","None required"))),"—")) -> Gc | AV11: =IF($C11="","",IFERROR(IF($AU11="None required","—",$AB11&" "&INDEX(Tables!$B$31:$B$37,MATCH($AA11-0.001,Tables!$A$31:$A$37,1))),"—")) -> IIA T2 | AW11: =IF($C11="","",TRIM(IF(IF(ISNUMBER($Z11),$H11<$Z11-5,FALSE()),"Handled >5°C below flash point — may not need zoning (unless mist/spray). ","")&IF(IF(AND($D11="Pool evaporation",ISNUMBER($Y11)),$H11>=$Y11,FALSE()),"Liquid at/above boiling point — pool equation not valid, treat as gas release. ","")&IF(IF(AND($D11="Liquid jet",$M11="",ISNUMBER($Y11)),$H11<$Y11,FALSE()),"Non-flashing liquid: vapour rate set to 0 — model the resulting pool on its own row. ","")&IF(AND($D11="Gas/vapour jet",NOT(ISNUMBER($W11))),"No γ in library for this substance. ","")&IF(IF(ISNUMBER($AC11),$AC11>1.2,FALSE()),"Heavier than air — extend zone at low level / into pits and drains. ","")&IF($AQ11="Low","Vz ≥ V0: ventilation cannot control the release — whole room affected. ","")&IF(AND($F11="Indoor",OR($Q11="",$R11="")),"Indoor: enter room volume and air changes. ",""))) -> Heavier than air — extend zone at low level / into pits and drains.
U12: =IF($C12="","",IFERROR(IF(INDEX(Substances!$C$2:$C$60,MATCH($C12,Substances!$A$2:$A$60,0))="","",INDEX(Substances!$C$2:$C$60,MATCH($C12,Substances!$A$2:$A$60,0))),"—")) | V12: =IF($C12="","",IFERROR(IF(INDEX(Substances!$D$2:$D$60,MATCH($C12,Substances!$A$2:$A$60,0))="","",INDEX(Substances!$D$2:$D$60,MATCH($C12,Substances!$A$2:$A$60,0))),"—")) | W12: =IF($C12="","",IFERROR(IF(INDEX(Substances!$F$2:$F$60,MATCH($C12,Substances!$A$2:$A$60,0))="","",INDEX(Substances!$F$2:$F$60,MATCH($C12,Substances!$A$2:$A$60,0))),"—")) | X12: =IF($C12="","",IFERROR(IF(INDEX(Substances!$G$2:$G$60,MATCH($C12,Substances!$A$2:$A$60,0))="","",INDEX(Substances!$G$2:$G$60,MATCH($C12,Substances!$A$2:$A$60,0))),"—")) | Y12: =IF($C12="","",IFERROR(IF(INDEX(Substances!$H$2:$H$60,MATCH($C12,Substances!$A$2:$A$60,0))="","",INDEX(Substances!$H$2:$H$60,MATCH($C12,Substances!$A$2:$A$60,0))),"—")) | Z12: =IF($C12="","",IFERROR(IF(INDEX(Substances!$I$2:$I$60,MATCH($C12,Substances!$A$2:$A$60,0))="","",INDEX(Substances!$I$2:$I$60,MATCH($C12,Substances!$A$2:$A$60,0))),"—")) | AA12: =IF($C12="","",IFERROR(IF(INDEX(Substances!$J$2:$J$60,MATCH($C12,Substances!$A$2:$A$60,0))="","",INDEX(Substances!$J$2:$J$60,MATCH($C12,Substances!$A$2:$A$60,0))),"—")) | AB12: =IF($C12="","",IFERROR(IF(INDEX(Substances!$K$2:$K$60,MATCH($C12,Substances!$A$2:$A$60,0))="","",INDEX(Substances!$K$2:$K$60,MATCH($C12,Substances!$A$2:$A$60,0))),"—")) | AC12: =IF($C12="","",IFERROR($U12/28.96,"—")) | AD12: =IF($C12="","",IFERROR(N($G12)*100000+Tables!$B$4,"—")) | AE12: =IF($C12="","",IFERROR($H12+273.15,"—")) | AF12: =IF($C12="","",IFERROR($I12+273.15,"—")) | AG12: =IF($C12="","",IFERROR(IF($D12="Gas/vapour jet",Tables!$B$4*(($W12+1)/2)^($W12/($W12-1)),"n/a"),"—")) | AH12: =IF($C12="","",IFERROR(IF($D12="Gas/vapour jet",IF($AD12>$AG12,"Choked","Subsonic"),"n/a"),"—")) | AI12: =IF($C12="","",IFERROR(IF($D12="Gas/vapour jet","n/a",MIN(101.325,IF($P12<>"",$P12,IF(N(INDEX(Substances!$L$2:$L$60,MATCH($C12,Substances!$A$2:$A$60,0)))<>0,0.133322*10^(INDEX(Substances!$L$2:$L$60,MATCH($C12,Substances!$A$2:$A$60,0))-INDEX(Substances!$M$2:$M$60,MATCH($C12,Substances!$A$2:$A$60,0))/(INDEX(Substances!$N$2:$N$60,MATCH($C12,Substances!$A$2:$A$60,0))+$H12)),101.325*EXP(10.58*(1-($Y12+273.15)/$AE12)))))),"—")) | AJ12: =IF($C12="","",IFERROR(IF($D12="Liquid jet",$K12*$J12*0.000001*SQRT(2*$X12*N($G12)*100000),"n/a"),"—")) | AK12: =IF($C12="","",IFERROR(IF($D12="Gas/vapour jet",IF($AH12="Choked",$K12*$J12*0.000001*$AD12*SQRT($W12*$U12/($L12*Tables!$B$5*$AE12)*(2/($W12+1))^(($W12+1)/($W12-1))),$K12*$J12*0.000001*$AD12*SQRT($U12/($L12*Tables!$B$5*$AE12)*(2*$W12/($W12-1))*(1-(Tables!$B$4/$AD12)^(($W12-1)/$W12))*(Tables!$B$4/$AD12)^(2/$W12))),IF($D12="Liquid jet",$AJ12*IF($M12<>"",$M12,IF($H12>=$Y12,1,0)),6.55*$O12^0.78*$N12*$AI12*$U12^0.667/(Tables!$B$5*$AE12))),"—")) | AL12: =IF($C12="","",IFERROR(Tables!$B$10*$U12*$V12,"—")) | AM12: =IF($C12="","",IFERROR(INDEX(Tables!$B$15:$B$17,MATCH($E12,Tables!$A$15:$A$17,0)),"—")) | AN12: =IF($C12="","",IFERROR($AK12/($AM12*$AL12)*$AF12/Tables!$B$9,"—")) | AO12: =IF($C12="","",IFERROR(IF($F12="Outdoor",Tables!$B$8,$R12/3600),"—")) | AP12: =IF($C12="","",IFERROR($S12*$AN12/$AO12,"—")) | AQ12: =IF($C12="","",IFERROR(IF($AP12<Tables!$B$7,"High",IF($F12="Outdoor","Medium",IF($AP12<$Q12,"Medium","Low"))),"—")) | AR12: =IF($C12="","",IFERROR(-$S12/$AO12*LN($V12*$AM12/Tables!$B$6)/60,"—")) | AS12: =IF($C12="","",IFERROR(INDEX(Tables!$B$22:$J$24,MATCH($E12,Tables!$A$22:$A$24,0),MATCH($AQ12&"-"&$T12,Tables!$B$21:$J$21,0)),"—")) | AT12: =IF($C12="","",IFERROR((3*$AP12/(2*PI()))^(1/3),"—")) | AU12: =IF($C12="","",IFERROR(IF(ISNUMBER(SEARCH("Zone 0",IFERROR(LEFT($AS12,FIND("(",$AS12)-1),$AS12))),"Ga",IF(ISNUMBER(SEARCH("Zone 1",IFERROR(LEFT($AS12,FIND("(",$AS12)-1),$AS12))),"Gb",IF(ISNUMBER(SEARCH("Zone 2",IFERROR(LEFT($AS12,FIND("(",$AS12)-1),$AS12))),"Gc","None required"))),"—")) | AV12: =IF($C12="","",IFERROR(IF($AU12="None required","—",$AB12&" "&INDEX(Tables!$B$31:$B$37,MATCH($AA12-0.001,Tables!$A$31:$A$37,1))),"—")) | AW12: =IF($C12="","",TRIM(IF(IF(ISNUMBER($Z12),$H12<$Z12-5,FALSE()),"Handled >5°C below flash point — may not need zoning (unless mist/spray). ","")&IF(IF(AND($D12="Pool evaporation",ISNUMBER($Y12)),$H12>=$Y12,FALSE()),"Liquid at/above boiling point — pool equation not valid, treat as gas release. ","")&IF(IF(AND($D12="Liquid jet",$M12="",ISNUMBER($Y12)),$H12<$Y12,FALSE()),"Non-flashing liquid: vapour rate set to 0 — model the resulting pool on its own row. ","")&IF(AND($D12="Gas/vapour jet",NOT(ISNUMBER($W12))),"No γ in library for this substance. ","")&IF(IF(ISNUMBER($AC12),$AC12>1.2,FALSE()),"Heavier than air — extend zone at low level / into pits and drains. ","")&IF($AQ12="Low","Vz ≥ V0: ventilation cannot control the release — whole room affected. ","")&IF(AND($F12="Indoor",OR($Q12="",$R12="")),"Indoor: enter room volume and air changes. ","")))
U13: =IF($C13="","",IFERROR(IF(INDEX(Substances!$C$2:$C$60,MATCH($C13,Substances!$A$2:$A$60,0))="","",INDEX(Substances!$C$2:$C$60,MATCH($C13,Substances!$A$2:$A$60,0))),"—")) | V13: =IF($C13="","",IFERROR(IF(INDEX(Substances!$D$2:$D$60,MATCH($C13,Substances!$A$2:$A$60,0))="","",INDEX(Substances!$D$2:$D$60,MATCH($C13,Substances!$A$2:$A$60,0))),"—")) | W13: =IF($C13="","",IFERROR(IF(INDEX(Substances!$F$2:$F$60,MATCH($C13,Substances!$A$2:$A$60,0))="","",INDEX(Substances!$F$2:$F$60,MATCH($C13,Substances!$A$2:$A$60,0))),"—")) | X13: =IF($C13="","",IFERROR(IF(INDEX(Substances!$G$2:$G$60,MATCH($C13,Substances!$A$2:$A$60,0))="","",INDEX(Substances!$G$2:$G$60,MATCH($C13,Substances!$A$2:$A$60,0))),"—")) | Y13: =IF($C13="","",IFERROR(IF(INDEX(Substances!$H$2:$H$60,MATCH($C13,Substances!$A$2:$A$60,0))="","",INDEX(Substances!$H$2:$H$60,MATCH($C13,Substances!$A$2:$A$60,0))),"—")) | Z13: =IF($C13="","",IFERROR(IF(INDEX(Substances!$I$2:$I$60,MATCH($C13,Substances!$A$2:$A$60,0))="","",INDEX(Substances!$I$2:$I$60,MATCH($C13,Substances!$A$2:$A$60,0))),"—")) | AA13: =IF($C13="","",IFERROR(IF(INDEX(Substances!$J$2:$J$60,MATCH($C13,Substances!$A$2:$A$60,0))="","",INDEX(Substances!$J$2:$J$60,MATCH($C13,Substances!$A$2:$A$60,0))),"—")) | AB13: =IF($C13="","",IFERROR(IF(INDEX(Substances!$K$2:$K$60,MATCH($C13,Substances!$A$2:$A$60,0))="","",INDEX(Substances!$K$2:$K$60,MATCH($C13,Substances!$A$2:$A$60,0))),"—")) | AC13: =IF($C13="","",IFERROR($U13/28.96,"—")) | AD13: =IF($C13="","",IFERROR(N($G13)*100000+Tables!$B$4,"—")) | AE13: =IF($C13="","",IFERROR($H13+273.15,"—")) | AF13: =IF($C13="","",IFERROR($I13+273.15,"—")) | AG13: =IF($C13="","",IFERROR(IF($D13="Gas/vapour jet",Tables!$B$4*(($W13+1)/2)^($W13/($W13-1)),"n/a"),"—")) | AH13: =IF($C13="","",IFERROR(IF($D13="Gas/vapour jet",IF($AD13>$AG13,"Choked","Subsonic"),"n/a"),"—")) | AI13: =IF($C13="","",IFERROR(IF($D13="Gas/vapour jet","n/a",MIN(101.325,IF($P13<>"",$P13,IF(N(INDEX(Substances!$L$2:$L$60,MATCH($C13,Substances!$A$2:$A$60,0)))<>0,0.133322*10^(INDEX(Substances!$L$2:$L$60,MATCH($C13,Substances!$A$2:$A$60,0))-INDEX(Substances!$M$2:$M$60,MATCH($C13,Substances!$A$2:$A$60,0))/(INDEX(Substances!$N$2:$N$60,MATCH($C13,Substances!$A$2:$A$60,0))+$H13)),101.325*EXP(10.58*(1-($Y13+273.15)/$AE13)))))),"—")) | AJ13: =IF($C13="","",IFERROR(IF($D13="Liquid jet",$K13*$J13*0.000001*SQRT(2*$X13*N($G13)*100000),"n/a"),"—")) | AK13: =IF($C13="","",IFERROR(IF($D13="Gas/vapour jet",IF($AH13="Choked",$K13*$J13*0.000001*$AD13*SQRT($W13*$U13/($L13*Tables!$B$5*$AE13)*(2/($W13+1))^(($W13+1)/($W13-1))),$K13*$J13*0.000001*$AD13*SQRT($U13/($L13*Tables!$B$5*$AE13)*(2*$W13/($W13-1))*(1-(Tables!$B$4/$AD13)^(($W13-1)/$W13))*(Tables!$B$4/$AD13)^(2/$W13))),IF($D13="Liquid jet",$AJ13*IF($M13<>"",$M13,IF($H13>=$Y13,1,0)),6.55*$O13^0.78*$N13*$AI13*$U13^0.667/(Tables!$B$5*$AE13))),"—")) | AL13: =IF($C13="","",IFERROR(Tables!$B$10*$U13*$V13,"—")) | AM13: =IF($C13="","",IFERROR(INDEX(Tables!$B$15:$B$17,MATCH($E13,Tables!$A$15:$A$17,0)),"—")) | AN13: =IF($C13="","",IFERROR($AK13/($AM13*$AL13)*$AF13/Tables!$B$9,"—")) | AO13: =IF($C13="","",IFERROR(IF($F13="Outdoor",Tables!$B$8,$R13/3600),"—")) | AP13: =IF($C13="","",IFERROR($S13*$AN13/$AO13,"—")) | AQ13: =IF($C13="","",IFERROR(IF($AP13<Tables!$B$7,"High",IF($F13="Outdoor","Medium",IF($AP13<$Q13,"Medium","Low"))),"—")) | AR13: =IF($C13="","",IFERROR(-$S13/$AO13*LN($V13*$AM13/Tables!$B$6)/60,"—")) | AS13: =IF($C13="","",IFERROR(INDEX(Tables!$B$22:$J$24,MATCH($E13,Tables!$A$22:$A$24,0),MATCH($AQ13&"-"&$T13,Tables!$B$21:$J$21,0)),"—")) | AT13: =IF($C13="","",IFERROR((3*$AP13/(2*PI()))^(1/3),"—")) | AU13: =IF($C13="","",IFERROR(IF(ISNUMBER(SEARCH("Zone 0",IFERROR(LEFT($AS13,FIND("(",$AS13)-1),$AS13))),"Ga",IF(ISNUMBER(SEARCH("Zone 1",IFERROR(LEFT($AS13,FIND("(",$AS13)-1),$AS13))),"Gb",IF(ISNUMBER(SEARCH("Zone 2",IFERROR(LEFT($AS13,FIND("(",$AS13)-1),$AS13))),"Gc","None required"))),"—")) | AV13: =IF($C13="","",IFERROR(IF($AU13="None required","—",$AB13&" "&INDEX(Tables!$B$31:$B$37,MATCH($AA13-0.001,Tables!$A$31:$A$37,1))),"—")) | AW13: =IF($C13="","",TRIM(IF(IF(ISNUMBER($Z13),$H13<$Z13-5,FALSE()),"Handled >5°C below flash point — may not need zoning (unless mist/spray). ","")&IF(IF(AND($D13="Pool evaporation",ISNUMBER($Y13)),$H13>=$Y13,FALSE()),"Liquid at/above boiling point — pool equation not valid, treat as gas release. ","")&IF(IF(AND($D13="Liquid jet",$M13="",ISNUMBER($Y13)),$H13<$Y13,FALSE()),"Non-flashing liquid: vapour rate set to 0 — model the resulting pool on its own row. ","")&IF(AND($D13="Gas/vapour jet",NOT(ISNUMBER($W13))),"No γ in library for this substance. ","")&IF(IF(ISNUMBER($AC13),$AC13>1.2,FALSE()),"Heavier than air — extend zone at low level / into pits and drains. ","")&IF($AQ13="Low","Vz ≥ V0: ventilation cannot control the release — whole room affected. ","")&IF(AND($F13="Indoor",OR($Q13="",$R13="")),"Indoor: enter room volume and air changes. ","")))
U14: =IF($C14="","",IFERROR(IF(INDEX(Substances!$C$2:$C$60,MATCH($C14,Substances!$A$2:$A$60,0))="","",INDEX(Substances!$C$2:$C$60,MATCH($C14,Substances!$A$2:$A$60,0))),"—")) | V14: =IF($C14="","",IFERROR(IF(INDEX(Substances!$D$2:$D$60,MATCH($C14,Substances!$A$2:$A$60,0))="","",INDEX(Substances!$D$2:$D$60,MATCH($C14,Substances!$A$2:$A$60,0))),"—")) | W14: =IF($C14="","",IFERROR(IF(INDEX(Substances!$F$2:$F$60,MATCH($C14,Substances!$A$2:$A$60,0))="","",INDEX(Substances!$F$2:$F$60,MATCH($C14,Substances!$A$2:$A$60,0))),"—")) | X14: =IF($C14="","",IFERROR(IF(INDEX(Substances!$G$2:$G$60,MATCH($C14,Substances!$A$2:$A$60,0))="","",INDEX(Substances!$G$2:$G$60,MATCH($C14,Substances!$A$2:$A$60,0))),"—")) | Y14: =IF($C14="","",IFERROR(IF(INDEX(Substances!$H$2:$H$60,MATCH($C14,Substances!$A$2:$A$60,0))="","",INDEX(Substances!$H$2:$H$60,MATCH($C14,Substances!$A$2:$A$60,0))),"—")) | Z14: =IF($C14="","",IFERROR(IF(INDEX(Substances!$I$2:$I$60,MATCH($C14,Substances!$A$2:$A$60,0))="","",INDEX(Substances!$I$2:$I$60,MATCH($C14,Substances!$A$2:$A$60,0))),"—")) | AA14: =IF($C14="","",IFERROR(IF(INDEX(Substances!$J$2:$J$60,MATCH($C14,Substances!$A$2:$A$60,0))="","",INDEX(Substances!$J$2:$J$60,MATCH($C14,Substances!$A$2:$A$60,0))),"—")) | AB14: =IF($C14="","",IFERROR(IF(INDEX(Substances!$K$2:$K$60,MATCH($C14,Substances!$A$2:$A$60,0))="","",INDEX(Substances!$K$2:$K$60,MATCH($C14,Substances!$A$2:$A$60,0))),"—")) | AC14: =IF($C14="","",IFERROR($U14/28.96,"—")) | AD14: =IF($C14="","",IFERROR(N($G14)*100000+Tables!$B$4,"—")) | AE14: =IF($C14="","",IFERROR($H14+273.15,"—")) | AF14: =IF($C14="","",IFERROR($I14+273.15,"—")) | AG14: =IF($C14="","",IFERROR(IF($D14="Gas/vapour jet",Tables!$B$4*(($W14+1)/2)^($W14/($W14-1)),"n/a"),"—")) | AH14: =IF($C14="","",IFERROR(IF($D14="Gas/vapour jet",IF($AD14>$AG14,"Choked","Subsonic"),"n/a"),"—")) | AI14: =IF($C14="","",IFERROR(IF($D14="Gas/vapour jet","n/a",MIN(101.325,IF($P14<>"",$P14,IF(N(INDEX(Substances!$L$2:$L$60,MATCH($C14,Substances!$A$2:$A$60,0)))<>0,0.133322*10^(INDEX(Substances!$L$2:$L$60,MATCH($C14,Substances!$A$2:$A$60,0))-INDEX(Substances!$M$2:$M$60,MATCH($C14,Substances!$A$2:$A$60,0))/(INDEX(Substances!$N$2:$N$60,MATCH($C14,Substances!$A$2:$A$60,0))+$H14)),101.325*EXP(10.58*(1-($Y14+273.15)/$AE14)))))),"—")) | AJ14: =IF($C14="","",IFERROR(IF($D14="Liquid jet",$K14*$J14*0.000001*SQRT(2*$X14*N($G14)*100000),"n/a"),"—")) | AK14: =IF($C14="","",IFERROR(IF($D14="Gas/vapour jet",IF($AH14="Choked",$K14*$J14*0.000001*$AD14*SQRT($W14*$U14/($L14*Tables!$B$5*$AE14)*(2/($W14+1))^(($W14+1)/($W14-1))),$K14*$J14*0.000001*$AD14*SQRT($U14/($L14*Tables!$B$5*$AE14)*(2*$W14/($W14-1))*(1-(Tables!$B$4/$AD14)^(($W14-1)/$W14))*(Tables!$B$4/$AD14)^(2/$W14))),IF($D14="Liquid jet",$AJ14*IF($M14<>"",$M14,IF($H14>=$Y14,1,0)),6.55*$O14^0.78*$N14*$AI14*$U14^0.667/(Tables!$B$5*$AE14))),"—")) | AL14: =IF($C14="","",IFERROR(Tables!$B$10*$U14*$V14,"—")) | AM14: =IF($C14="","",IFERROR(INDEX(Tables!$B$15:$B$17,MATCH($E14,Tables!$A$15:$A$17,0)),"—")) | AN14: =IF($C14="","",IFERROR($AK14/($AM14*$AL14)*$AF14/Tables!$B$9,"—")) | AO14: =IF($C14="","",IFERROR(IF($F14="Outdoor",Tables!$B$8,$R14/3600),"—")) | AP14: =IF($C14="","",IFERROR($S14*$AN14/$AO14,"—")) | AQ14: =IF($C14="","",IFERROR(IF($AP14<Tables!$B$7,"High",IF($F14="Outdoor","Medium",IF($AP14<$Q14,"Medium","Low"))),"—")) | AR14: =IF($C14="","",IFERROR(-$S14/$AO14*LN($V14*$AM14/Tables!$B$6)/60,"—")) | AS14: =IF($C14="","",IFERROR(INDEX(Tables!$B$22:$J$24,MATCH($E14,Tables!$A$22:$A$24,0),MATCH($AQ14&"-"&$T14,Tables!$B$21:$J$21,0)),"—")) | AT14: =IF($C14="","",IFERROR((3*$AP14/(2*PI()))^(1/3),"—")) | AU14: =IF($C14="","",IFERROR(IF(ISNUMBER(SEARCH("Zone 0",IFERROR(LEFT($AS14,FIND("(",$AS14)-1),$AS14))),"Ga",IF(ISNUMBER(SEARCH("Zone 1",IFERROR(LEFT($AS14,FIND("(",$AS14)-1),$AS14))),"Gb",IF(ISNUMBER(SEARCH("Zone 2",IFERROR(LEFT($AS14,FIND("(",$AS14)-1),$AS14))),"Gc","None required"))),"—")) | AV14: =IF($C14="","",IFERROR(IF($AU14="None required","—",$AB14&" "&INDEX(Tables!$B$31:$B$37,MATCH($AA14-0.001,Tables!$A$31:$A$37,1))),"—")) | AW14: =IF($C14="","",TRIM(IF(IF(ISNUMBER($Z14),$H14<$Z14-5,FALSE()),"Handled >5°C below flash point — may not need zoning (unless mist/spray). ","")&IF(IF(AND($D14="Pool evaporation",ISNUMBER($Y14)),$H14>=$Y14,FALSE()),"Liquid at/above boiling point — pool equation not valid, treat as gas release. ","")&IF(IF(AND($D14="Liquid jet",$M14="",ISNUMBER($Y14)),$H14<$Y14,FALSE()),"Non-flashing liquid: vapour rate set to 0 — model the resulting pool on its own row. ","")&IF(AND($D14="Gas/vapour jet",NOT(ISNUMBER($W14))),"No γ in library for this substance. ","")&IF(IF(ISNUMBER($AC14),$AC14>1.2,FALSE()),"Heavier than air — extend zone at low level / into pits and drains. ","")&IF($AQ14="Low","Vz ≥ V0: ventilation cannot control the release — whole room affected. ","")&IF(AND($F14="Indoor",OR($Q14="",$R14="")),"Indoor: enter room volume and air changes. ","")))
U15: =IF($C15="","",IFERROR(IF(INDEX(Substances!$C$2:$C$60,MATCH($C15,Substances!$A$2:$A$60,0))="","",INDEX(Substances!$C$2:$C$60,MATCH($C15,Substances!$A$2:$A$60,0))),"—")) | V15: =IF($C15="","",IFERROR(IF(INDEX(Substances!$D$2:$D$60,MATCH($C15,Substances!$A$2:$A$60,0))="","",INDEX(Substances!$D$2:$D$60,MATCH($C15,Substances!$A$2:$A$60,0))),"—")) | W15: =IF($C15="","",IFERROR(IF(INDEX(Substances!$F$2:$F$60,MATCH($C15,Substances!$A$2:$A$60,0))="","",INDEX(Substances!$F$2:$F$60,MATCH($C15,Substances!$A$2:$A$60,0))),"—")) | X15: =IF($C15="","",IFERROR(IF(INDEX(Substances!$G$2:$G$60,MATCH($C15,Substances!$A$2:$A$60,0))="","",INDEX(Substances!$G$2:$G$60,MATCH($C15,Substances!$A$2:$A$60,0))),"—")) | Y15: =IF($C15="","",IFERROR(IF(INDEX(Substances!$H$2:$H$60,MATCH($C15,Substances!$A$2:$A$60,0))="","",INDEX(Substances!$H$2:$H$60,MATCH($C15,Substances!$A$2:$A$60,0))),"—")) | Z15: =IF($C15="","",IFERROR(IF(INDEX(Substances!$I$2:$I$60,MATCH($C15,Substances!$A$2:$A$60,0))="","",INDEX(Substances!$I$2:$I$60,MATCH($C15,Substances!$A$2:$A$60,0))),"—")) | AA15: =IF($C15="","",IFERROR(IF(INDEX(Substances!$J$2:$J$60,MATCH($C15,Substances!$A$2:$A$60,0))="","",INDEX(Substances!$J$2:$J$60,MATCH($C15,Substances!$A$2:$A$60,0))),"—")) | AB15: =IF($C15="","",IFERROR(IF(INDEX(Substances!$K$2:$K$60,MATCH($C15,Substances!$A$2:$A$60,0))="","",INDEX(Substances!$K$2:$K$60,MATCH($C15,Substances!$A$2:$A$60,0))),"—")) | AC15: =IF($C15="","",IFERROR($U15/28.96,"—")) | AD15: =IF($C15="","",IFERROR(N($G15)*100000+Tables!$B$4,"—")) | AE15: =IF($C15="","",IFERROR($H15+273.15,"—")) | AF15: =IF($C15="","",IFERROR($I15+273.15,"—")) | AG15: =IF($C15="","",IFERROR(IF($D15="Gas/vapour jet",Tables!$B$4*(($W15+1)/2)^($W15/($W15-1)),"n/a"),"—")) | AH15: =IF($C15="","",IFERROR(IF($D15="Gas/vapour jet",IF($AD15>$AG15,"Choked","Subsonic"),"n/a"),"—")) | AI15: =IF($C15="","",IFERROR(IF($D15="Gas/vapour jet","n/a",MIN(101.325,IF($P15<>"",$P15,IF(N(INDEX(Substances!$L$2:$L$60,MATCH($C15,Substances!$A$2:$A$60,0)))<>0,0.133322*10^(INDEX(Substances!$L$2:$L$60,MATCH($C15,Substances!$A$2:$A$60,0))-INDEX(Substances!$M$2:$M$60,MATCH($C15,Substances!$A$2:$A$60,0))/(INDEX(Substances!$N$2:$N$60,MATCH($C15,Substances!$A$2:$A$60,0))+$H15)),101.325*EXP(10.58*(1-($Y15+273.15)/$AE15)))))),"—")) | AJ15: =IF($C15="","",IFERROR(IF($D15="Liquid jet",$K15*$J15*0.000001*SQRT(2*$X15*N($G15)*100000),"n/a"),"—")) | AK15: =IF($C15="","",IFERROR(IF($D15="Gas/vapour jet",IF($AH15="Choked",$K15*$J15*0.000001*$AD15*SQRT($W15*$U15/($L15*Tables!$B$5*$AE15)*(2/($W15+1))^(($W15+1)/($W15-1))),$K15*$J15*0.000001*$AD15*SQRT($U15/($L15*Tables!$B$5*$AE15)*(2*$W15/($W15-1))*(1-(Tables!$B$4/$AD15)^(($W15-1)/$W15))*(Tables!$B$4/$AD15)^(2/$W15))),IF($D15="Liquid jet",$AJ15*IF($M15<>"",$M15,IF($H15>=$Y15,1,0)),6.55*$O15^0.78*$N15*$AI15*$U15^0.667/(Tables!$B$5*$AE15))),"—")) | AL15: =IF($C15="","",IFERROR(Tables!$B$10*$U15*$V15,"—")) | AM15: =IF($C15="","",IFERROR(INDEX(Tables!$B$15:$B$17,MATCH($E15,Tables!$A$15:$A$17,0)),"—")) | AN15: =IF($C15="","",IFERROR($AK15/($AM15*$AL15)*$AF15/Tables!$B$9,"—")) | AO15: =IF($C15="","",IFERROR(IF($F15="Outdoor",Tables!$B$8,$R15/3600),"—")) | AP15: =IF($C15="","",IFERROR($S15*$AN15/$AO15,"—")) | AQ15: =IF($C15="","",IFERROR(IF($AP15<Tables!$B$7,"High",IF($F15="Outdoor","Medium",IF($AP15<$Q15,"Medium","Low"))),"—")) | AR15: =IF($C15="","",IFERROR(-$S15/$AO15*LN($V15*$AM15/Tables!$B$6)/60,"—")) | AS15: =IF($C15="","",IFERROR(INDEX(Tables!$B$22:$J$24,MATCH($E15,Tables!$A$22:$A$24,0),MATCH($AQ15&"-"&$T15,Tables!$B$21:$J$21,0)),"—")) | AT15: =IF($C15="","",IFERROR((3*$AP15/(2*PI()))^(1/3),"—")) | AU15: =IF($C15="","",IFERROR(IF(ISNUMBER(SEARCH("Zone 0",IFERROR(LEFT($AS15,FIND("(",$AS15)-1),$AS15))),"Ga",IF(ISNUMBER(SEARCH("Zone 1",IFERROR(LEFT($AS15,FIND("(",$AS15)-1),$AS15))),"Gb",IF(ISNUMBER(SEARCH("Zone 2",IFERROR(LEFT($AS15,FIND("(",$AS15)-1),$AS15))),"Gc","None required"))),"—")) | AV15: =IF($C15="","",IFERROR(IF($AU15="None required","—",$AB15&" "&INDEX(Tables!$B$31:$B$37,MATCH($AA15-0.001,Tables!$A$31:$A$37,1))),"—")) | AW15: =IF($C15="","",TRIM(IF(IF(ISNUMBER($Z15),$H15<$Z15-5,FALSE()),"Handled >5°C below flash point — may not need zoning (unless mist/spray). ","")&IF(IF(AND($D15="Pool evaporation",ISNUMBER($Y15)),$H15>=$Y15,FALSE()),"Liquid at/above boiling point — pool equation not valid, treat as gas release. ","")&IF(IF(AND($D15="Liquid jet",$M15="",ISNUMBER($Y15)),$H15<$Y15,FALSE()),"Non-flashing liquid: vapour rate set to 0 — model the resulting pool on its own row. ","")&IF(AND($D15="Gas/vapour jet",NOT(ISNUMBER($W15))),"No γ in library for this substance. ","")&IF(IF(ISNUMBER($AC15),$AC15>1.2,FALSE()),"Heavier than air — extend zone at low level / into pits and drains. ","")&IF($AQ15="Low","Vz ≥ V0: ventilation cannot control the release — whole room affected. ","")&IF(AND($F15="Indoor",OR($Q15="",$R15="")),"Indoor: enter room volume and air changes. ","")))
U16: =IF($C16="","",IFERROR(IF(INDEX(Substances!$C$2:$C$60,MATCH($C16,Substances!$A$2:$A$60,0))="","",INDEX(Substances!$C$2:$C$60,MATCH($C16,Substances!$A$2:$A$60,0))),"—")) | V16: =IF($C16="","",IFERROR(IF(INDEX(Substances!$D$2:$D$60,MATCH($C16,Substances!$A$2:$A$60,0))="","",INDEX(Substances!$D$2:$D$60,MATCH($C16,Substances!$A$2:$A$60,0))),"—")) | W16: =IF($C16="","",IFERROR(IF(INDEX(Substances!$F$2:$F$60,MATCH($C16,Substances!$A$2:$A$60,0))="","",INDEX(Substances!$F$2:$F$60,MATCH($C16,Substances!$A$2:$A$60,0))),"—")) | X16: =IF($C16="","",IFERROR(IF(INDEX(Substances!$G$2:$G$60,MATCH($C16,Substances!$A$2:$A$60,0))="","",INDEX(Substances!$G$2:$G$60,MATCH($C16,Substances!$A$2:$A$60,0))),"—")) | Y16: =IF($C16="","",IFERROR(IF(INDEX(Substances!$H$2:$H$60,MATCH($C16,Substances!$A$2:$A$60,0))="","",INDEX(Substances!$H$2:$H$60,MATCH($C16,Substances!$A$2:$A$60,0))),"—")) | Z16: =IF($C16="","",IFERROR(IF(INDEX(Substances!$I$2:$I$60,MATCH($C16,Substances!$A$2:$A$60,0))="","",INDEX(Substances!$I$2:$I$60,MATCH($C16,Substances!$A$2:$A$60,0))),"—")) | AA16: =IF($C16="","",IFERROR(IF(INDEX(Substances!$J$2:$J$60,MATCH($C16,Substances!$A$2:$A$60,0))="","",INDEX(Substances!$J$2:$J$60,MATCH($C16,Substances!$A$2:$A$60,0))),"—")) | AB16: =IF($C16="","",IFERROR(IF(INDEX(Substances!$K$2:$K$60,MATCH($C16,Substances!$A$2:$A$60,0))="","",INDEX(Substances!$K$2:$K$60,MATCH($C16,Substances!$A$2:$A$60,0))),"—")) | AC16: =IF($C16="","",IFERROR($U16/28.96,"—")) | AD16: =IF($C16="","",IFERROR(N($G16)*100000+Tables!$B$4,"—")) | AE16: =IF($C16="","",IFERROR($H16+273.15,"—")) | AF16: =IF($C16="","",IFERROR($I16+273.15,"—")) | AG16: =IF($C16="","",IFERROR(IF($D16="Gas/vapour jet",Tables!$B$4*(($W16+1)/2)^($W16/($W16-1)),"n/a"),"—")) | AH16: =IF($C16="","",IFERROR(IF($D16="Gas/vapour jet",IF($AD16>$AG16,"Choked","Subsonic"),"n/a"),"—")) | AI16: =IF($C16="","",IFERROR(IF($D16="Gas/vapour jet","n/a",MIN(101.325,IF($P16<>"",$P16,IF(N(INDEX(Substances!$L$2:$L$60,MATCH($C16,Substances!$A$2:$A$60,0)))<>0,0.133322*10^(INDEX(Substances!$L$2:$L$60,MATCH($C16,Substances!$A$2:$A$60,0))-INDEX(Substances!$M$2:$M$60,MATCH($C16,Substances!$A$2:$A$60,0))/(INDEX(Substances!$N$2:$N$60,MATCH($C16,Substances!$A$2:$A$60,0))+$H16)),101.325*EXP(10.58*(1-($Y16+273.15)/$AE16)))))),"—")) | AJ16: =IF($C16="","",IFERROR(IF($D16="Liquid jet",$K16*$J16*0.000001*SQRT(2*$X16*N($G16)*100000),"n/a"),"—")) | AK16: =IF($C16="","",IFERROR(IF($D16="Gas/vapour jet",IF($AH16="Choked",$K16*$J16*0.000001*$AD16*SQRT($W16*$U16/($L16*Tables!$B$5*$AE16)*(2/($W16+1))^(($W16+1)/($W16-1))),$K16*$J16*0.000001*$AD16*SQRT($U16/($L16*Tables!$B$5*$AE16)*(2*$W16/($W16-1))*(1-(Tables!$B$4/$AD16)^(($W16-1)/$W16))*(Tables!$B$4/$AD16)^(2/$W16))),IF($D16="Liquid jet",$AJ16*IF($M16<>"",$M16,IF($H16>=$Y16,1,0)),6.55*$O16^0.78*$N16*$AI16*$U16^0.667/(Tables!$B$5*$AE16))),"—")) | AL16: =IF($C16="","",IFERROR(Tables!$B$10*$U16*$V16,"—")) | AM16: =IF($C16="","",IFERROR(INDEX(Tables!$B$15:$B$17,MATCH($E16,Tables!$A$15:$A$17,0)),"—")) | AN16: =IF($C16="","",IFERROR($AK16/($AM16*$AL16)*$AF16/Tables!$B$9,"—")) | AO16: =IF($C16="","",IFERROR(IF($F16="Outdoor",Tables!$B$8,$R16/3600),"—")) | AP16: =IF($C16="","",IFERROR($S16*$AN16/$AO16,"—")) | AQ16: =IF($C16="","",IFERROR(IF($AP16<Tables!$B$7,"High",IF($F16="Outdoor","Medium",IF($AP16<$Q16,"Medium","Low"))),"—")) | AR16: =IF($C16="","",IFERROR(-$S16/$AO16*LN($V16*$AM16/Tables!$B$6)/60,"—")) | AS16: =IF($C16="","",IFERROR(INDEX(Tables!$B$22:$J$24,MATCH($E16,Tables!$A$22:$A$24,0),MATCH($AQ16&"-"&$T16,Tables!$B$21:$J$21,0)),"—")) | AT16: =IF($C16="","",IFERROR((3*$AP16/(2*PI()))^(1/3),"—")) | AU16: =IF($C16="","",IFERROR(IF(ISNUMBER(SEARCH("Zone 0",IFERROR(LEFT($AS16,FIND("(",$AS16)-1),$AS16))),"Ga",IF(ISNUMBER(SEARCH("Zone 1",IFERROR(LEFT($AS16,FIND("(",$AS16)-1),$AS16))),"Gb",IF(ISNUMBER(SEARCH("Zone 2",IFERROR(LEFT($AS16,FIND("(",$AS16)-1),$AS16))),"Gc","None required"))),"—")) | AV16: =IF($C16="","",IFERROR(IF($AU16="None required","—",$AB16&" "&INDEX(Tables!$B$31:$B$37,MATCH($AA16-0.001,Tables!$A$31:$A$37,1))),"—")) | AW16: =IF($C16="","",TRIM(IF(IF(ISNUMBER($Z16),$H16<$Z16-5,FALSE()),"Handled >5°C below flash point — may not need zoning (unless mist/spray). ","")&IF(IF(AND($D16="Pool evaporation",ISNUMBER($Y16)),$H16>=$Y16,FALSE()),"Liquid at/above boiling point — pool equation not valid, treat as gas release. ","")&IF(IF(AND($D16="Liquid jet",$M16="",ISNUMBER($Y16)),$H16<$Y16,FALSE()),"Non-flashing liquid: vapour rate set to 0 — model the resulting pool on its own row. ","")&IF(AND($D16="Gas/vapour jet",NOT(ISNUMBER($W16))),"No γ in library for this substance. ","")&IF(IF(ISNUMBER($AC16),$AC16>1.2,FALSE()),"Heavier than air — extend zone at low level / into pits and drains. ","")&IF($AQ16="Low","Vz ≥ V0: ventilation cannot control the release — whole room affected. ","")&IF(AND($F16="Indoor",OR($Q16="",$R16="")),"Indoor: enter room volume and air changes. ","")))
